Workbook

Sheet Jan
A1: LAPORAN KEUANGAN
A2: RT03/RW21 BUKIT PERMAI Januari 2026
A4: Penerimaan | D4: Pengeluaran
A5: No | B5: Keterangan | C5: Pemasukan | D5: No | E5: Keterangan | F5: Beban
A6: =IFERROR(__xludf.DUMMYFUNCTION("QUERY('+Jan'!A65:H79, ""SELECT Col1, Col2, Col8 where Col8 > 0"", 1)"),"1") -> 1 | B6: =IFERROR(__xludf.DUMMYFUNCTION("""COMPUTED_VALUE"""),"Pak Heri Wurdi (Jan 2026 - Des 2026)") -> Pak Heri Wurdi (Jan 2026 - Des 2026) | C6: =IFERROR(__xludf.DUMMYFUNCTION("""COMPUTED_VALUE""")," Rp 660.000 ") -> Rp 660.000 | D6: =IFERROR(__xludf.DUMMYFUNCTION("QUERY('-Jan'!A2:H34, ""SELECT Col1, Col2, Col8 where Col8 > 0"")"),1.0) -> 1 | E6: =IFERROR(__xludf.DUMMYFUNCTION("""COMPUTED_VALUE"""),"Iuran Penjaga Keamanan") -> Iuran Penjaga Keamanan | F6: =IFERROR(__xludf.DUMMYFUNCTION("""COMPUTED_VALUE"""),600000.0) -> 600000
A7: =IFERROR(__xludf.DUMMYFUNCTION("""COMPUTED_VALUE"""),2.0) -> 2 | B7: =IFERROR(__xludf.DUMMYFUNCTION("""COMPUTED_VALUE"""),"Wat Tak (Jan 2026 - Des 2026)") -> Wat Tak (Jan 2026 - Des 2026) | C7: =IFERROR(__xludf.DUMMYFUNCTION("""COMPUTED_VALUE"""),655000.0) -> 655000 | D7: =IFERROR(__xludf.DUMMYFUNCTION("""COMPUTED_VALUE"""),2.0) -> 2 | E7: =IFERROR(__xludf.DUMMYFUNCTION("""COMPUTED_VALUE"""),"Iuran Retribusi Sampah") -> Iuran Retribusi Sampah | F7: =IFERROR(__xludf.DUMMYFUNCTION("""COMPUTED_VALUE"""),75000.0) -> 75000
A8: =IFERROR(__xludf.DUMMYFUNCTION("""COMPUTED_VALUE"""),3.0) -> 3 | B8: =IFERROR(__xludf.DUMMYFUNCTION("""COMPUTED_VALUE"""),"Total Dama Bu Ifa") -> Total Dama Bu Ifa | C8: =IFERROR(__xludf.DUMMYFUNCTION("""COMPUTED_VALUE"""),790000.0) -> 790000 | D8: =IFERROR(__xludf.DUMMYFUNCTION("""COMPUTED_VALUE"""),3.0) -> 3 | E8: =IFERROR(__xludf.DUMMYFUNCTION("""COMPUTED_VALUE"""),"Iuran Tukang Sampah") -> Iuran Tukang Sampah | F8: =IFERROR(__xludf.DUMMYFUNCTION("""COMPUTED_VALUE"""),750000.0) -> 750000
A9: =IFERROR(__xludf.DUMMYFUNCTION("""COMPUTED_VALUE"""),4.0) -> 4 | B9: =IFERROR(__xludf.DUMMYFUNCTION("""COMPUTED_VALUE"""),"Total Dama Bu Nur") -> Total Dama Bu Nur | C9: =IFERROR(__xludf.DUMMYFUNCTION("""COMPUTED_VALUE"""),700000.0) -> 700000 | D9: =IFERROR(__xludf.DUMMYFUNCTION("""COMPUTED_VALUE"""),4.0) -> 4 | E9: =IFERROR(__xludf.DUMMYFUNCTION("""COMPUTED_VALUE"""),"Setor Rukem (Jan - Feb)") -> Setor Rukem (Jan - Feb) | F9: =IFERROR(__xludf.DUMMYFUNCTION("""COMPUTED_VALUE"""),400000.0) -> 400000
A10: =IFERROR(__xludf.DUMMYFUNCTION("""COMPUTED_VALUE"""),5.0) -> 5 | B10: =IFERROR(__xludf.DUMMYFUNCTION("""COMPUTED_VALUE"""),"Total Dama Bu Desi") -> Total Dama Bu Desi | C10: =IFERROR(__xludf.DUMMYFUNCTION("""COMPUTED_VALUE"""),600000.0) -> 600000 | D10: =IFERROR(__xludf.DUMMYFUNCTION("""COMPUTED_VALUE"""),5.0) -> 5 | E10: =IFERROR(__xludf.DUMMYFUNCTION("""COMPUTED_VALUE"""),"Setor RW (Jan - Feb)") -> Setor RW (Jan - Feb) | F10: =IFERROR(__xludf.DUMMYFUNCTION("""COMPUTED_VALUE"""),200000.0) -> 200000
A11: =IFERROR(__xludf.DUMMYFUNCTION("""COMPUTED_VALUE"""),6.0) -> 6 | B11: =IFERROR(__xludf.DUMMYFUNCTION("""COMPUTED_VALUE"""),"Saldo Sebelumnya") -> Saldo Sebelumnya | C11: =IFERROR(__xludf.DUMMYFUNCTION("""COMPUTED_VALUE"""),1.3366E7) -> 13366000 | D11: =IFERROR(__xludf.DUMMYFUNCTION("""COMPUTED_VALUE"""),6.0) -> 6 | E11: =IFERROR(__xludf.DUMMYFUNCTION("""COMPUTED_VALUE"""),"Iuran Rapat RT") -> Iuran Rapat RT | F11: =IFERROR(__xludf.DUMMYFUNCTION("""COMPUTED_VALUE"""),150000.0) -> 150000
B26: Total Penerimaan | C26: =SUM(C6:C22) -> 16111000 | E26: Total Pengeluaran | F26: =SUM(F6:F22) -> 2175000
E27: Saldo akhir | F27: =SUM(C26-F26) -> 13936000
B32: Rincian Pos
B33: Sampah dan Keamanan | C33: ='+Jan'!C80 - '-Jan'!C35 -> 6379500
B34: Kematian | C34: ='+Jan'!D80 - '-Jan'!D35 -> 1407000
B35: Iuran RT | C35: ='+Jan'!E80 - '-Jan'!E35 -> 3123500
B36: Iuran RW | C36: ='+Jan'!F80 - '-Jan'!F35 -> 942500
B37: HUT | C37: ='+Jan'!G80 - '-Jan'!G36 -> 2083500
B38: Total | C38: =SUM(C33:C37) -> 13936000

Sheet Feb
A1: LAPORAN KEUANGAN
A2: RT03/RW21 BUKIT PERMAI Februari 2026
A4: Penerimaan | D4: Pengeluaran
A5: No | B5: Keterangan | C5: Pemasukan | D5: No | E5: Keterangan | F5: Beban
A6: =IFERROR(__xludf.DUMMYFUNCTION("QUERY('+Feb'!A65:H79, ""SELECT Col1, Col2, Col8 where Col8 > 0"", 1)"),"1") -> 1 | B6: =IFERROR(__xludf.DUMMYFUNCTION("""COMPUTED_VALUE"""),"Pak Sulton (Jan 2026 - Juli 2026)") -> Pak Sulton (Jan 2026 - Juli 2026) | C6: =IFERROR(__xludf.DUMMYFUNCTION("""COMPUTED_VALUE""")," Rp 330.000 ") -> Rp 330.000 | D6: =IFERROR(__xludf.DUMMYFUNCTION("QUERY('-Feb'!A2:H34, ""SELECT Col1, Col2, Col8 where Col8 > 0"")"),1.0) -> 1 | E6: =IFERROR(__xludf.DUMMYFUNCTION("""COMPUTED_VALUE"""),"Iuran Penjaga Keamanan") -> Iuran Penjaga Keamanan | F6: =IFERROR(__xludf.DUMMYFUNCTION("""COMPUTED_VALUE"""),600000.0) -> 600000
A7: =IFERROR(__xludf.DUMMYFUNCTION("""COMPUTED_VALUE"""),2.0) -> 2 | B7: =IFERROR(__xludf.DUMMYFUNCTION("""COMPUTED_VALUE"""),"Khotti (Jan 2026 - Des 2026)") -> Khotti (Jan 2026 - Des 2026) | C7: =IFERROR(__xludf.DUMMYFUNCTION("""COMPUTED_VALUE"""),660000.0) -> 660000 | D7: =IFERROR(__xludf.DUMMYFUNCTION("""COMPUTED_VALUE"""),2.0) -> 2 | E7: =IFERROR(__xludf.DUMMYFUNCTION("""COMPUTED_VALUE"""),"Iuran Retribusi Sampah") -> Iuran Retribusi Sampah | F7: =IFERROR(__xludf.DUMMYFUNCTION("""COMPUTED_VALUE"""),75000.0) -> 75000
A8: =IFERROR(__xludf.DUMMYFUNCTION("""COMPUTED_VALUE"""),3.0) -> 3 | B8: =IFERROR(__xludf.DUMMYFUNCTION("""COMPUTED_VALUE"""),"Yunita (Jan 2026 - Des 2026)") -> Yunita (Jan 2026 - Des 2026) | C8: =IFERROR(__xludf.DUMMYFUNCTION("""COMPUTED_VALUE"""),660000.0) -> 660000 | D8: =IFERROR(__xludf.DUMMYFUNCTION("""COMPUTED_VALUE"""),3.0) -> 3 | E8: =IFERROR(__xludf.DUMMYFUNCTION("""COMPUTED_VALUE"""),"Iuran Tukang Sampah") -> Iuran Tukang Sampah | F8: =IFERROR(__xludf.DUMMYFUNCTION("""COMPUTED_VALUE"""),750000.0) -> 750000
A9: =IFERROR(__xludf.DUMMYFUNCTION("""COMPUTED_VALUE"""),4.0) -> 4 | B9: =IFERROR(__xludf.DUMMYFUNCTION("""COMPUTED_VALUE"""),"Total Dama Bu Ifa") -> Total Dama Bu Ifa | C9: =IFERROR(__xludf.DUMMYFUNCTION("""COMPUTED_VALUE"""),920000.0) -> 920000 | D9: =IFERROR(__xludf.DUMMYFUNCTION("""COMPUTED_VALUE"""),4.0) -> 4 | E9: =IFERROR(__xludf.DUMMYFUNCTION("""COMPUTED_VALUE"""),"THR Tukang Sampah") -> THR Tukang Sampah | F9: =IFERROR(__xludf.DUMMYFUNCTION("""COMPUTED_VALUE"""),750000.0) -> 750000
A10: =IFERROR(__xludf.DUMMYFUNCTION("""COMPUTED_VALUE"""),5.0) -> 5 | B10: =IFERROR(__xludf.DUMMYFUNCTION("""COMPUTED_VALUE"""),"Total Dama Bu Nur") -> Total Dama Bu Nur | C10: =IFERROR(__xludf.DUMMYFUNCTION("""COMPUTED_VALUE"""),770000.0) -> 770000 | D10: =IFERROR(__xludf.DUMMYFUNCTION("""COMPUTED_VALUE"""),5.0) -> 5 | E10: =IFERROR(__xludf.DUMMYFUNCTION("""COMPUTED_VALUE"""),"THR Keamanan") -> THR Keamanan | F10: =IFERROR(__xludf.DUMMYFUNCTION("""COMPUTED_VALUE"""),600000.0) -> 600000
A11: =IFERROR(__xludf.DUMMYFUNCTION("""COMPUTED_VALUE"""),6.0) -> 6 | B11: =IFERROR(__xludf.DUMMYFUNCTION("""COMPUTED_VALUE"""),"Total Dama Bu Desi") -> Total Dama Bu Desi | C11: =IFERROR(__xludf.DUMMYFUNCTION("""COMPUTED_VALUE"""),660000.0) -> 660000 | D11: =IFERROR(__xludf.DUMMYFUNCTION("""COMPUTED_VALUE"""),6.0) -> 6 | E11: =IFERROR(__xludf.DUMMYFUNCTION("""COMPUTED_VALUE"""),"Parcel Lebaran") -> Parcel Lebaran | F11: =IFERROR(__xludf.DUMMYFUNCTION("""COMPUTED_VALUE"""),900000.0) -> 900000
A12: =IFERROR(__xludf.DUMMYFUNCTION("""COMPUTED_VALUE"""),7.0) -> 7 | B12: =IFERROR(__xludf.DUMMYFUNCTION("""COMPUTED_VALUE"""),"Saldo Sebelumnya") -> Saldo Sebelumnya | C12: =IFERROR(__xludf.DUMMYFUNCTION("""COMPUTED_VALUE"""),1.3936E7) -> 13936000
B26: Total Penerimaan | C26: =SUM(C6:C22) -> 17606000 | E26: Total Pengeluaran | F26: =SUM(F6:F22) -> 3675000
E27: Saldo akhir | F27: =SUM(C26-F26) -> 13931000
B32: Rincian Pos | E32: Pengeluaran | F32: Delta
B33: Sampah dan Keamanan | C33: ='+Feb'!C80 - '-Feb'!C35 -> 5949500 | E33: ='-Feb'!C35 -> 2775000 | F33: =C33-Jan!C33 -> -430000
B34: Kematian | C34: ='+Feb'!D80 - '-Feb'!D35 -> 1742000 | E34: ='-Feb'!D35 -> 0 | F34: =C34-Jan!C34 -> 335000
B35: Iuran RT | C35: ='+Feb'!E80 - '-Feb'!E35 -> 2388500 | E35: ='-Feb'!E35 -> 900000 | F35: =C35-Jan!C35 -> -735000
B36: Iuran RW | C36: ='+Feb'!F80 - '-Feb'!F35 -> 1107500 | E36: ='-Feb'!F35 -> 0 | F36: =C36-Jan!C36 -> 165000
B37: HUT | C37: ='+Feb'!G80 - '-Feb'!G35 -> 2743500 | E37: ='-Feb'!G35 -> 0 | F37: =C37-Jan!C37 -> 660000
B38: Total | C38: =SUM(C33:C37) -> 13931000 | E38: =SUM(E33:E37) -> 3675000 | F38: =C38-Jan!C38 -> -5000

Sheet Mar
A1: LAPORAN KEUANGAN
A2: RT03/RW21 BUKIT PERMAI Maret 2026
A4: Penerimaan | D4: Pengeluaran
A5: No | B5: Keterangan | C5: Pemasukan | D5: No | E5: Keterangan | F5: Beban
A6: =IFERROR(__xludf.DUMMYFUNCTION("QUERY('+Mar'!A65:H79, ""SELECT Col1, Col2, Col8 where Col8 > 0"", 1)"),"1") -> 1 | B6: =IFERROR(__xludf.DUMMYFUNCTION("""COMPUTED_VALUE"""),"Yayasan") -> Yayasan | C6: =IFERROR(__xludf.DUMMYFUNCTION("""COMPUTED_VALUE""")," Rp 100.000 ") -> Rp 100.000 | D6: =IFERROR(__xludf.DUMMYFUNCTION("QUERY('-Mar'!A2:H34, ""SELECT Col1, Col2, Col8 where Col8 > 0"")"),1.0) -> 1 | E6: =IFERROR(__xludf.DUMMYFUNCTION("""COMPUTED_VALUE"""),"Iuran Penjaga Keamanan") -> Iuran Penjaga Keamanan | F6: =IFERROR(__xludf.DUMMYFUNCTION("""COMPUTED_VALUE"""),600000.0) -> 600000
A7: =IFERROR(__xludf.DUMMYFUNCTION("""COMPUTED_VALUE"""),2.0) -> 2 | B7: =IFERROR(__xludf.DUMMYFUNCTION("""COMPUTED_VALUE"""),"Bu Glen (Des '25 - Feb '26)") -> Bu Glen (Des '25 - Feb '26) | C7: =IFERROR(__xludf.DUMMYFUNCTION("""COMPUTED_VALUE"""),160000.0) -> 160000 | D7: =IFERROR(__xludf.DUMMYFUNCTION("""COMPUTED_VALUE"""),2.0) -> 2 | E7: =IFERROR(__xludf.DUMMYFUNCTION("""COMPUTED_VALUE"""),"Iuran Retribusi Sampah") -> Iuran Retribusi Sampah | F7: =IFERROR(__xludf.DUMMYFUNCTION("""COMPUTED_VALUE"""),75000.0) -> 75000
A8: =IFERROR(__xludf.DUMMYFUNCTION("""COMPUTED_VALUE"""),2.0) -> 2 | B8: =IFERROR(__xludf.DUMMYFUNCTION("""COMPUTED_VALUE"""),"Total Dama Bu Ifa") -> Total Dama Bu Ifa | C8: =IFERROR(__xludf.DUMMYFUNCTION("""COMPUTED_VALUE"""),810000.0) -> 810000 | D8: =IFERROR(__xludf.DUMMYFUNCTION("""COMPUTED_VALUE"""),3.0) -> 3 | E8: =IFERROR(__xludf.DUMMYFUNCTION("""COMPUTED_VALUE"""),"Iuran Tukang Sampah") -> Iuran Tukang Sampah | F8: =IFERROR(__xludf.DUMMYFUNCTION("""COMPUTED_VALUE"""),750000.0) -> 750000
A9: =IFERROR(__xludf.DUMMYFUNCTION("""COMPUTED_VALUE"""),3.0) -> 3 | B9: =IFERROR(__xludf.DUMMYFUNCTION("""COMPUTED_VALUE"""),"Total Dama Bu Nur") -> Total Dama Bu Nur | C9: =IFERROR(__xludf.DUMMYFUNCTION("""COMPUTED_VALUE"""),800000.0) -> 800000 | D9: =IFERROR(__xludf.DUMMYFUNCTION("""COMPUTED_VALUE"""),4.0) -> 4 | E9: =IFERROR(__xludf.DUMMYFUNCTION("""COMPUTED_VALUE"""),"Setor Rukem (Mar - Apr)") -> Setor Rukem (Mar - Apr) | F9: =IFERROR(__xludf.DUMMYFUNCTION("""COMPUTED_VALUE"""),400000.0) -> 400000
A10: =IFERROR(__xludf.DUMMYFUNCTION("""COMPUTED_VALUE"""),4.0) -> 4 | B10: =IFERROR(__xludf.DUMMYFUNCTION("""COMPUTED_VALUE"""),"Total Dama Bu Desi") -> Total Dama Bu Desi | C10: =IFERROR(__xludf.DUMMYFUNCTION("""COMPUTED_VALUE"""),660000.0) -> 660000 | D10: =IFERROR(__xludf.DUMMYFUNCTION("""COMPUTED_VALUE"""),5.0) -> 5 | E10: =IFERROR(__xludf.DUMMYFUNCTION("""COMPUTED_VALUE"""),"Setor RW (Mar - Apr)") -> Setor RW (Mar - Apr) | F10: =IFERROR(__xludf.DUMMYFUNCTION("""COMPUTED_VALUE"""),200000.0) -> 200000
A11: =IFERROR(__xludf.DUMMYFUNCTION("""COMPUTED_VALUE"""),5.0) -> 5 | B11: =IFERROR(__xludf.DUMMYFUNCTION("""COMPUTED_VALUE"""),"Saldo Sebelumnya") -> Saldo Sebelumnya | C11: =IFERROR(__xludf.DUMMYFUNCTION("""COMPUTED_VALUE"""),1.3931E7) -> 13931000
B26: Total Penerimaan | C26: =SUM(C6:C22) -> 16361000 | E26: Total Pengeluaran | F26: =SUM(F6:F22) -> 2025000
E27: Saldo akhir | F27: =SUM(C26-F26) -> 14336000
B32: Rincian Pos | E32: Pengeluaran | F32: Delta
B33: Sampah dan Keamanan | C33: ='+Mar'!C80 - '-Mar'!C35 -> 6094500 | E33: ='-Mar'!C35 -> 1425000 | F33: =C33-Feb!C33 -> 145000
B34: Kematian | C34: ='+Mar'!D80 - '-Mar'!D35 -> 1562000 | E34: ='-Mar'!D35 -> 400000 | F34: =C34-Feb!C34 -> -180000
B35: Iuran RT | C35: ='+Mar'!E80 - '-Mar'!E35 -> 2496000 | E35: ='-Mar'!E35 -> 0 | F35: =C35-Feb!C35 -> 107500
B36: Iuran RW | C36: ='+Mar'!F80 - '-Mar'!F35 -> 1015000 | E36: ='-Mar'!F35 -> 200000 | F36: =C36-Feb!C36 -> -92500
B37: HUT | C37: ='+Mar'!G80 - '-Mar'!G35 -> 3168500 | E37: ='-Mar'!G35 -> 0 | F37: =C37-Feb!C37 -> 425000
B38: Total | C38: =SUM(C33:C37) -> 14336000 | E38: =SUM(E33:E37) -> 2025000 | F38: =C38-Feb!C38 -> 405000

Sheet Apr
A1: LAPORAN KEUANGAN
A2: RT03/RW21 BUKIT PERMAI April 2026
A4: Penerimaan | D4: Pengeluaran
A5: No | B5: Keterangan | C5: Pemasukan | D5: No | E5: Keterangan | F5: Beban
A6: =IFERROR(__xludf.DUMMYFUNCTION("QUERY('+Apr'!A65:H79, ""SELECT Col1, Col2, Col8 where Col8 > 0"", 1)"),1.0) -> 1 | B6: =IFERROR(__xludf.DUMMYFUNCTION("""COMPUTED_VALUE"""),"Total Dama Bu Ifa") -> Total Dama Bu Ifa | C6: =IFERROR(__xludf.DUMMYFUNCTION("""COMPUTED_VALUE"""),865000.0) -> 865000 | D6: =IFERROR(__xludf.DUMMYFUNCTION("QUERY('-Apr'!A2:H34, ""SELECT Col1, Col2, Col8 where Col8 > 0"")"),1.0) -> 1 | E6: =IFERROR(__xludf.DUMMYFUNCTION("""COMPUTED_VALUE"""),"Iuran Penjaga Keamanan") -> Iuran Penjaga Keamanan | F6: =IFERROR(__xludf.DUMMYFUNCTION("""COMPUTED_VALUE"""),600000.0) -> 600000
A7: =IFERROR(__xludf.DUMMYFUNCTION("""COMPUTED_VALUE"""),2.0) -> 2 | B7: =IFERROR(__xludf.DUMMYFUNCTION("""COMPUTED_VALUE"""),"Total Dama Bu Nur") -> Total Dama Bu Nur | C7: =IFERROR(__xludf.DUMMYFUNCTION("""COMPUTED_VALUE"""),820000.0) -> 820000 | D7: =IFERROR(__xludf.DUMMYFUNCTION("""COMPUTED_VALUE"""),2.0) -> 2 | E7: =IFERROR(__xludf.DUMMYFUNCTION("""COMPUTED_VALUE"""),"Iuran Retribusi Sampah") -> Iuran Retribusi Sampah | F7: =IFERROR(__xludf.DUMMYFUNCTION("""COMPUTED_VALUE"""),75000.0) -> 75000
A8: =IFERROR(__xludf.DUMMYFUNCTION("""COMPUTED_VALUE"""),3.0) -> 3 | B8: =IFERROR(__xludf.DUMMYFUNCTION("""COMPUTED_VALUE"""),"Total Dama Bu Desi") -> Total Dama Bu Desi | C8: =IFERROR(__xludf.DUMMYFUNCTION("""COMPUTED_VALUE"""),660000.0) -> 660000 | D8: =IFERROR(__xludf.DUMMYFUNCTION("""COMPUTED_VALUE"""),3.0) -> 3 | E8: =IFERROR(__xludf.DUMMYFUNCTION("""COMPUTED_VALUE"""),"Iuran Tukang Sampah") -> Iuran Tukang Sampah | F8: =IFERROR(__xludf.DUMMYFUNCTION("""COMPUTED_VALUE"""),750000.0) -> 750000
A9: =IFERROR(__xludf.DUMMYFUNCTION("""COMPUTED_VALUE"""),4.0) -> 4 | B9: =IFERROR(__xludf.DUMMYFUNCTION("""COMPUTED_VALUE"""),"Saldo Sebelumnya") -> Saldo Sebelumnya | C9: =IFERROR(__xludf.DUMMYFUNCTION("""COMPUTED_VALUE"""),1.4336E7) -> 14336000 | D9: =IFERROR(__xludf.DUMMYFUNCTION("""COMPUTED_VALUE"""),4.0) -> 4 | E9: =IFERROR(__xludf.DUMMYFUNCTION("""COMPUTED_VALUE"""),"Iuran Rapat Warga") -> Iuran Rapat Warga | F9: =IFERROR(__xludf.DUMMYFUNCTION("""COMPUTED_VALUE"""),1970000.0) -> 1970000
B26: Total Penerimaan | C26: =SUM(C6:C22) -> 16681000 | E26: Total Pengeluaran | F26: =SUM(F6:F22) -> 3395000
E27: Saldo akhir | F27: =SUM(C26-F26) -> 13286000
B32: Rincian Pos
B33: Sampah dan Keamanan | C33: ='+Apr'!C80 - '-Apr'!C35 -> 6169500
B34: Kematian | C34: ='+Apr'!D80 - '-Apr'!D35 -> 1777000
B35: Iuran RT | C35: ='+Apr'!E80 - '-Apr'!E35 -> 631000
B36: Iuran RW | C36: ='+Apr'!F80 - '-Apr'!F35 -> 1120000
B37: HUT | C37: ='+Apr'!G80 - '-Apr'!G35 -> 3588500
B38: Total | C38: =SUM(C33:C37) -> 13286000

Sheet Mei
A1: LAPORAN KEUANGAN
A2: RT03/RW21 BUKIT PERMAI Mei 2026
A4: Penerimaan | D4: Pengeluaran
A5: No | B5: Keterangan | C5: Pemasukan | D5: No | E5: Keterangan | F5: Beban
A6: =IFERROR(__xludf.DUMMYFUNCTION("QUERY('+Mei'!A65:H79, ""SELECT Col1, Col2, Col8 where Col8 > 0"", 1)"),"1") -> 1 | B6: =IFERROR(__xludf.DUMMYFUNCTION("""COMPUTED_VALUE"""),"Bu Glen (Mar - Mei '26)") -> Bu Glen (Mar - Mei '26) | C6: =IFERROR(__xludf.DUMMYFUNCTION("""COMPUTED_VALUE"""),"") | D6: =IFERROR(__xludf.DUMMYFUNCTION("QUERY('-Mei'!A2:H34, ""SELECT Col1, Col2, Col8 where Col8 > 0"")"),1.0) -> 1 | E6: =IFERROR(__xludf.DUMMYFUNCTION("""COMPUTED_VALUE"""),"Iuran Penjaga Keamanan") -> Iuran Penjaga Keamanan | F6: =IFERROR(__xludf.DUMMYFUNCTION("""COMPUTED_VALUE"""),600000.0) -> 600000
A7: =IFERROR(__xludf.DUMMYFUNCTION("""COMPUTED_VALUE"""),2.0) -> 2 | B7: =IFERROR(__xludf.DUMMYFUNCTION("""COMPUTED_VALUE"""),"Total Dama Bu Ifa") -> Total Dama Bu Ifa | C7: =IFERROR(__xludf.DUMMYFUNCTION("""COMPUTED_VALUE"""),810000.0) -> 810000 | D7: =IFERROR(__xludf.DUMMYFUNCTION("""COMPUTED_VALUE"""),2.0) -> 2 | E7: =IFERROR(__xludf.DUMMYFUNCTION("""COMPUTED_VALUE"""),"Iuran Retribusi Sampah") -> Iuran Retribusi Sampah | F7: =IFERROR(__xludf.DUMMYFUNCTION("""COMPUTED_VALUE"""),75000.0) -> 75000
A8: =IFERROR(__xludf.DUMMYFUNCTION("""COMPUTED_VALUE"""),3.0) -> 3 | B8: =IFERROR(__xludf.DUMMYFUNCTION("""COMPUTED_VALUE"""),"Total Dama Bu Nur") -> Total Dama Bu Nur | C8: =IFERROR(__xludf.DUMMYFUNCTION("""COMPUTED_VALUE"""),840000.0) -> 840000 | D8: =IFERROR(__xludf.DUMMYFUNCTION("""COMPUTED_VALUE"""),3.0) -> 3 | E8: =IFERROR(__xludf.DUMMYFUNCTION("""COMPUTED_VALUE"""),"Iuran Tukang Sampah") -> Iuran Tukang Sampah | F8: =IFERROR(__xludf.DUMMYFUNCTION("""COMPUTED_VALUE"""),750000.0) -> 750000
A9: =IFERROR(__xludf.DUMMYFUNCTION("""COMPUTED_VALUE"""),5.0) -> 5 | B9: =IFERROR(__xludf.DUMMYFUNCTION("""COMPUTED_VALUE"""),"Saldo Sebelumnya") -> Saldo Sebelumnya | C9: =IFERROR(__xludf.DUMMYFUNCTION("""COMPUTED_VALUE"""),1.3286E7) -> 13286000 | D9: =IFERROR(__xludf.DUMMYFUNCTION("""COMPUTED_VALUE"""),4.0) -> 4 | E9: =IFERROR(__xludf.DUMMYFUNCTION("""COMPUTED_VALUE"""),"Setor Rukem (Mei - Jun)") -> Setor Rukem (Mei - Jun) | F9: =IFERROR(__xludf.DUMMYFUNCTION("""COMPUTED_VALUE"""),400000.0) -> 400000
D10: =IFERROR(__xludf.DUMMYFUNCTION("""COMPUTED_VALUE"""),5.0) -> 5 | E10: =IFERROR(__xludf.DUMMYFUNCTION("""COMPUTED_VALUE"""),"Setor RW (Mei - Jun)") -> Setor RW (Mei - Jun) | F10: =IFERROR(__xludf.DUMMYFUNCTION("""COMPUTED_VALUE"""),200000.0) -> 200000
B26: Total Penerimaan | C26: =SUM(C6:C22) -> 14936000 | E26: Total Pengeluaran | F26: =SUM(F6:F22) -> 2025000
E27: Saldo akhir | F27: =SUM(C26-F26) -> 12911000
B32: Rincian Pos
B33: Sampah dan Keamanan | C33: ='+Mei'!C80 - '-Mei'!C35 -> 5789500
B34: Kematian | C34: ='+Mei'!D80 - '-Mei'!D35 -> 1532000
B35: Iuran RT | C35: ='+Mei'!E80 - '-Mei'!E35 -> 706000
B36: Iuran RW | C36: ='+Mei'!F80 - '-Mei'!F35 -> 995000
B37: HUT | C37: ='+Mei'!G80 - '-Mei'!G35 -> 3888500
B38: Total | C38: =SUM(C33:C37) -> 12911000

Sheet Jun
A1: LAPORAN KEUANGAN
A2: RT03/RW21 BUKIT PERMAI Juni 2026
A4: Penerimaan | D4: Pengeluaran
A5: No | B5: Keterangan | C5: Pemasukan | D5: No | E5: Keterangan | F5: Beban
A6: =IFERROR(__xludf.DUMMYFUNCTION("QUERY('+Jun'!A65:H79, ""SELECT Col1, Col2, Col8 where Col8 > 0"", 1)"),1.0) -> 1 | B6: =IFERROR(__xludf.DUMMYFUNCTION("""COMPUTED_VALUE"""),"Total Dama Bu Ifa") -> Total Dama Bu Ifa | C6: =IFERROR(__xludf.DUMMYFUNCTION("""COMPUTED_VALUE"""),810000.0) -> 810000 | D6: =IFERROR(__xludf.DUMMYFUNCTION("QUERY('-Jun'!A2:H34, ""SELECT Col1, Col2, Col8 where Col8 > 0"")"),1.0) -> 1 | E6: =IFERROR(__xludf.DUMMYFUNCTION("""COMPUTED_VALUE"""),"Iuran Penjaga Keamanan") -> Iuran Penjaga Keamanan | F6: =IFERROR(__xludf.DUMMYFUNCTION("""COMPUTED_VALUE"""),600000.0) -> 600000
A7: =IFERROR(__xludf.DUMMYFUNCTION("""COMPUTED_VALUE"""),4.0) -> 4 | B7: =IFERROR(__xludf.DUMMYFUNCTION("""COMPUTED_VALUE"""),"Saldo Sebelumnya") -> Saldo Sebelumnya | C7: =IFERROR(__xludf.DUMMYFUNCTION("""COMPUTED_VALUE"""),1.2911E7) -> 12911000 | D7: =IFERROR(__xludf.DUMMYFUNCTION("""COMPUTED_VALUE"""),2.0) -> 2 | E7: =IFERROR(__xludf.DUMMYFUNCTION("""COMPUTED_VALUE"""),"Iuran Retribusi Sampah") -> Iuran Retribusi Sampah | F7: =IFERROR(__xludf.DUMMYFUNCTION("""COMPUTED_VALUE"""),75000.0) -> 75000
D8: =IFERROR(__xludf.DUMMYFUNCTION("""COMPUTED_VALUE"""),3.0) -> 3 | E8: =IFERROR(__xludf.DUMMYFUNCTION("""COMPUTED_VALUE"""),"Iuran Tukang Sampah") -> Iuran Tukang Sampah | F8: =IFERROR(__xludf.DUMMYFUNCTION("""COMPUTED_VALUE"""),750000.0) -> 750000
B26: Total Penerimaan | C26: =SUM(C6:C22) -> 13721000 | E26: Total Pengeluaran | F26: =SUM(F6:F22) -> 1425000
E27: Saldo akhir | F27: =SUM(C26-F26) -> 12296000
B32: Rincian Pos
B33: Sampah dan Keamanan | C33: ='+Jun'!C80 - '-Jun'!C35 -> 4889500
B34: Kematian | C34: ='+Jun'!D80 - '-Jun'!D35 -> 1607000
B35: Iuran RT | C35: ='+Jun'!E80 - '-Jun'!E35 -> 741000
B36: Iuran RW | C36: ='+Jun'!F80 - '-Jun'!F35 -> 1030000
B37: HUT | C37: ='+Jun'!G80 - '-Jun'!G35 -> 4028500
B38: Total | C38: =SUM(C33:C37) -> 12296000

Sheet Jul
A1: LAPORAN KEUANGAN
A2: RT03/RW21 BUKIT PERMAI Juli 2026
A4: Penerimaan | D4: Pengeluaran
A5: No | B5: Keterangan | C5: Pemasukan | D5: No | E5: Keterangan | F5: Beban
A6: =IFERROR(__xludf.DUMMYFUNCTION("QUERY('+Jul'!A65:H79, ""SELECT Col1, Col2, Col8 where Col8 > 0"", 1)"),4.0) -> 4 | B6: =IFERROR(__xludf.DUMMYFUNCTION("""COMPUTED_VALUE"""),"Saldo Sebelumnya") -> Saldo Sebelumnya | C6: =IFERROR(__xludf.DUMMYFUNCTION("""COMPUTED_VALUE"""),1.2296E7) -> 12296000 | D6: =IFERROR(__xludf.DUMMYFUNCTION("QUERY('-Jul'!A2:H34, ""SELECT Col1, Col2, Col8 where Col8 > 0"")"),1.0) -> 1 | E6: =IFERROR(__xludf.DUMMYFUNCTION("""COMPUTED_VALUE"""),"Iuran Penjaga Keamanan") -> Iuran Penjaga Keamanan | F6: =IFERROR(__xludf.DUMMYFUNCTION("""COMPUTED_VALUE"""),600000.0) -> 600000
D7: =IFERROR(__xludf.DUMMYFUNCTION("""COMPUTED_VALUE"""),2.0) -> 2 | E7: =IFERROR(__xludf.DUMMYFUNCTION("""COMPUTED_VALUE"""),"Iuran Retribusi Sampah") -> Iuran Retribusi Sampah | F7: =IFERROR(__xludf.DUMMYFUNCTION("""COMPUTED_VALUE"""),75000.0) -> 75000
D8: =IFERROR(__xludf.DUMMYFUNCTION("""COMPUTED_VALUE"""),3.0) -> 3 | E8: =IFERROR(__xludf.DUMMYFUNCTION("""COMPUTED_VALUE"""),"Iuran Tukang Sampah") -> Iuran Tukang Sampah | F8: =IFERROR(__xludf.DUMMYFUNCTION("""COMPUTED_VALUE"""),750000.0) -> 750000
B26: Total Penerimaan | C26: =SUM(C6:C22) -> 12296000 | E26: Total Pengeluaran | F26: =SUM(F6:F22) -> 1425000
E27: Saldo akhir | F27: =SUM(C26-F26) -> 10871000
B32: Rincian Pos
B33: Sampah dan Keamanan | C33: ='+Jul'!C80 - '-Jul'!C35 -> 3464500
B34: Kematian | C34: ='+Jul'!D80 - '-Jul'!D35 -> 1607000
B35: Iuran RT | C35: ='+Jul'!E80 - '-Jul'!E35 -> 741000
B36: Iuran RW | C36: ='+Jul'!F80 - '-Jul'!F35 -> 1030000
B37: HUT | C37: ='+Jul'!G80 - '-Jul'!G35 -> 4028500
B38: Total | C38: =SUM(C33:C37) -> 10871000

Sheet Agu
A1: LAPORAN KEUANGAN
A2: RT03/RW21 BUKIT PERMAI Agustus 2026
A4: Penerimaan | D4: Pengeluaran
A5: No | B5: Keterangan | C5: Pemasukan | D5: No | E5: Keterangan | F5: Beban
A6: =IFERROR(__xludf.DUMMYFUNCTION("QUERY('+Agu'!A65:H79, ""SELECT Col1, Col2, Col8 where Col8 > 0"", 1)"),4.0) -> 4 | B6: =IFERROR(__xludf.DUMMYFUNCTION("""COMPUTED_VALUE"""),"Saldo Sebelumnya") -> Saldo Sebelumnya | C6: =IFERROR(__xludf.DUMMYFUNCTION("""COMPUTED_VALUE"""),1.0871E7) -> 10871000 | D6: =IFERROR(__xludf.DUMMYFUNCTION("QUERY('-Agu'!A2:H34, ""SELECT Col1, Col2, Col8 where Col8 > 0"")"),1.0) -> 1 | E6: =IFERROR(__xludf.DUMMYFUNCTION("""COMPUTED_VALUE"""),"Iuran Penjaga Keamanan") -> Iuran Penjaga Keamanan | F6: =IFERROR(__xludf.DUMMYFUNCTION("""COMPUTED_VALUE"""),600000.0) -> 600000
D7: =IFERROR(__xludf.DUMMYFUNCTION("""COMPUTED_VALUE"""),2.0) -> 2 | E7: =IFERROR(__xludf.DUMMYFUNCTION("""COMPUTED_VALUE"""),"Iuran Retribusi Sampah") -> Iuran Retribusi Sampah | F7: =IFERROR(__xludf.DUMMYFUNCTION("""COMPUTED_VALUE"""),75000.0) -> 75000
D8: =IFERROR(__xludf.DUMMYFUNCTION("""COMPUTED_VALUE"""),3.0) -> 3 | E8: =IFERROR(__xludf.DUMMYFUNCTION("""COMPUTED_VALUE"""),"Iuran Tukang Sampah") -> Iuran Tukang Sampah | F8: =IFERROR(__xludf.DUMMYFUNCTION("""COMPUTED_VALUE"""),750000.0) -> 750000
B26: Total Penerimaan | C26: =SUM(C6:C22) -> 10871000 | E26: Total Pengeluaran | F26: =SUM(F6:F22) -> 1425000
E27: Saldo akhir | F27: =SUM(C26-F26) -> 9446000
B32: Rincian Pos
B33: Sampah dan Keamanan | C33: ='+Agu'!C80 - '-Agu'!C35 -> 2039500
B34: Kematian | C34: ='+Agu'!D80 - '-Agu'!D35 -> 1607000
B35: Iuran RT | C35: ='+Agu'!E80 - '-Agu'!E35 -> 741000
B36: Iuran RW | C36: ='+Agu'!F80 - '-Agu'!F35 -> 1030000
B37: HUT | C37: ='+Agu'!G80 - '-Agu'!G35 -> 4028500
B38: Total | C38: =SUM(C33:C37) -> 9446000

Sheet Sep
A1: LAPORAN KEUANGAN
A2: RT03/RW21 BUKIT PERMAI September 2026
A4: Penerimaan | D4: Pengeluaran
A5: No | B5: Keterangan | C5: Pemasukan | D5: No | E5: Keterangan | F5: Beban
A6: =IFERROR(__xludf.DUMMYFUNCTION("QUERY('+Sep'!A65:H79, ""SELECT Col1, Col2, Col8 where Col8 > 0"", 1)"),4.0) -> 4 | B6: =IFERROR(__xludf.DUMMYFUNCTION("""COMPUTED_VALUE"""),"Saldo Sebelumnya") -> Saldo Sebelumnya | C6: =IFERROR(__xludf.DUMMYFUNCTION("""COMPUTED_VALUE"""),9446000.0) -> 9446000 | D6: =IFERROR(__xludf.DUMMYFUNCTION("QUERY('-Sep'!A2:H34, ""SELECT Col1, Col2, Col8 where Col8 > 0"")"),1.0) -> 1 | E6: =IFERROR(__xludf.DUMMYFUNCTION("""COMPUTED_VALUE"""),"Iuran Penjaga Keamanan") -> Iuran Penjaga Keamanan | F6: =IFERROR(__xludf.DUMMYFUNCTION("""COMPUTED_VALUE"""),600000.0) -> 600000
D7: =IFERROR(__xludf.DUMMYFUNCTION("""COMPUTED_VALUE"""),2.0) -> 2 | E7: =IFERROR(__xludf.DUMMYFUNCTION("""COMPUTED_VALUE"""),"Iuran Retribusi Sampah") -> Iuran Retribusi Sampah | F7: =IFERROR(__xludf.DUMMYFUNCTION("""COMPUTED_VALUE"""),75000.0) -> 75000
D8: =IFERROR(__xludf.DUMMYFUNCTION("""COMPUTED_VALUE"""),3.0) -> 3 | E8: =IFERROR(__xludf.DUMMYFUNCTION("""COMPUTED_VALUE"""),"Iuran Tukang Sampah") -> Iuran Tukang Sampah | F8: =IFERROR(__xludf.DUMMYFUNCTION("""COMPUTED_VALUE"""),750000.0) -> 750000
B26: Total Penerimaan | C26: =SUM(C6:C22) -> 9446000 | E26: Total Pengeluaran | F26: =SUM(F6:F22) -> 1425000
E27: Saldo akhir | F27: =SUM(C26-F26) -> 8021000
B32: Rincian Pos
B33: Sampah dan Keamanan | C33: ='+Sep'!C80 - '-Sep'!C35 -> 614500
B34: Kematian | C34: ='+Sep'!D80 - '-Sep'!D35 -> 1607000
B35: Iuran RT | C35: ='+Sep'!E80 - '-Sep'!E35 -> 741000
B36: Iuran RW | C36: ='+Sep'!F80 - '-Sep'!F35 -> 1030000
B37: HUT | C37: ='+Sep'!G80 - '-Sep'!G35 -> 4028500
B38: Total | C38: =SUM(C33:C37) -> 8021000

Sheet Okt
A1: LAPORAN KEUANGAN
A2: RT03/RW21 BUKIT PERMAI Oktober 2026
A4: Penerimaan | D4: Pengeluaran
A5: No | B5: Keterangan | C5: Pemasukan | D5: No | E5: Keterangan | F5: Beban
A6: =IFERROR(__xludf.DUMMYFUNCTION("QUERY('+Okt'!A65:H79, ""SELECT Col1, Col2, Col8 where Col8 > 0"", 1)"),4.0) -> 4 | B6: =IFERROR(__xludf.DUMMYFUNCTION("""COMPUTED_VALUE"""),"Saldo Sebelumnya") -> Saldo Sebelumnya | C6: =IFERROR(__xludf.DUMMYFUNCTION("""COMPUTED_VALUE"""),8021000.0) -> 8021000 | D6: =IFERROR(__xludf.DUMMYFUNCTION("QUERY('-Okt'!A2:H34, ""SELECT Col1, Col2, Col8 where Col8 > 0"")"),1.0) -> 1 | E6: =IFERROR(__xludf.DUMMYFUNCTION("""COMPUTED_VALUE"""),"Iuran Penjaga Keamanan") -> Iuran Penjaga Keamanan | F6: =IFERROR(__xludf.DUMMYFUNCTION("""COMPUTED_VALUE"""),600000.0) -> 600000
D7: =IFERROR(__xludf.DUMMYFUNCTION("""COMPUTED_VALUE"""),2.0) -> 2 | E7: =IFERROR(__xludf.DUMMYFUNCTION("""COMPUTED_VALUE"""),"Iuran Retribusi Sampah") -> Iuran Retribusi Sampah | F7: =IFERROR(__xludf.DUMMYFUNCTION("""COMPUTED_VALUE"""),75000.0) -> 75000
D8: =IFERROR(__xludf.DUMMYFUNCTION("""COMPUTED_VALUE"""),3.0) -> 3 | E8: =IFERROR(__xludf.DUMMYFUNCTION("""COMPUTED_VALUE"""),"Iuran Tukang Sampah") -> Iuran Tukang Sampah | F8: =IFERROR(__xludf.DUMMYFUNCTION("""COMPUTED_VALUE"""),750000.0) -> 750000
B26: Total Penerimaan | C26: =SUM(C6:C22) -> 8021000 | E26: Total Pengeluaran | F26: =SUM(F6:F22) -> 1425000
E27: Saldo akhir | F27: =SUM(C26-F26) -> 6596000
B32: Rincian Pos
B33: Sampah dan Keamanan | C33: ='+Okt'!C80 - '-Okt'!C35 -> -810500
B34: Kematian | C34: ='+Okt'!D80 - '-Okt'!D35 -> 1607000
B35: Iuran RT | C35: ='+Okt'!E80 - '-Okt'!E35 -> 741000
B36: Iuran RW | C36: ='+Okt'!F80 - '-Okt'!F35 -> 1030000
B37: HUT | C37: ='+Okt'!G80 - '-Okt'!G35 -> 4028500
B38: Total | C38: =SUM(C33:C37) -> 6596000

Sheet Nov
A1: LAPORAN KEUANGAN
A2: RT03/RW21 BUKIT PERMAI November 2026
A4: Penerimaan | D4: Pengeluaran
A5: No | B5: Keterangan | C5: Pemasukan | D5: No | E5: Keterangan | F5: Beban
A6: =IFERROR(__xludf.DUMMYFUNCTION("QUERY('+Nov'!A65:H79, ""SELECT Col1, Col2, Col8 where Col8 > 0"", 1)"),4.0) -> 4 | B6: =IFERROR(__xludf.DUMMYFUNCTION("""COMPUTED_VALUE"""),"Saldo Sebelumnya") -> Saldo Sebelumnya | C6: =IFERROR(__xludf.DUMMYFUNCTION("""COMPUTED_VALUE"""),6596000.0) -> 6596000 | D6: =IFERROR(__xludf.DUMMYFUNCTION("QUERY('-Nov'!A2:H34, ""SELECT Col1, Col2, Col8 where Col8 > 0"")"),1.0) -> 1 | E6: =IFERROR(__xludf.DUMMYFUNCTION("""COMPUTED_VALUE"""),"Iuran Penjaga Keamanan") -> Iuran Penjaga Keamanan | F6: =IFERROR(__xludf.DUMMYFUNCTION("""COMPUTED_VALUE"""),600000.0) -> 600000
D7: =IFERROR(__xludf.DUMMYFUNCTION("""COMPUTED_VALUE"""),2.0) -> 2 | E7: =IFERROR(__xludf.DUMMYFUNCTION("""COMPUTED_VALUE"""),"Iuran Retribusi Sampah") -> Iuran Retribusi Sampah | F7: =IFERROR(__xludf.DUMMYFUNCTION("""COMPUTED_VALUE"""),75000.0) -> 75000
D8: =IFERROR(__xludf.DUMMYFUNCTION("""COMPUTED_VALUE"""),3.0) -> 3 | E8: =IFERROR(__xludf.DUMMYFUNCTION("""COMPUTED_VALUE"""),"Iuran Tukang Sampah") -> Iuran Tukang Sampah | F8: =IFERROR(__xludf.DUMMYFUNCTION("""COMPUTED_VALUE"""),750000.0) -> 750000
B26: Total Penerimaan | C26: =SUM(C6:C22) -> 6596000 | E26: Total Pengeluaran | F26: =SUM(F6:F22) -> 1425000
E27: Saldo akhir | F27: =SUM(C26-F26) -> 5171000
B32: Rincian Pos
B33: Sampah dan Keamanan | C33: ='+Nov'!C80 - '-Nov'!C35 -> -2235500
B34: Kematian | C34: ='+Nov'!D80 - '-Nov'!D35 -> 1607000
B35: Iuran RT | C35: ='+Nov'!E80 - '-Nov'!E35 -> 741000
B36: Iuran RW | C36: ='+Nov'!F80 - '-Nov'!F35 -> 1030000
B37: HUT | C37: ='+Nov'!G80 - '-Nov'!G35 -> 4028500
B38: Total | C38: =SUM(C33:C37) -> 5171000

Sheet Des
A1: LAPORAN KEUANGAN
A2: RT03/RW21 BUKIT PERMAI Desember 2026
A4: Penerimaan | D4: Pengeluaran
A5: No | B5: Keterangan | C5: Pemasukan | D5: No | E5: Keterangan | F5: Beban
A6: =IFERROR(__xludf.DUMMYFUNCTION("QUERY('+Des'!A65:H79, ""SELECT Col1, Col2, Col8 where Col8 > 0"", 1)"),4.0) -> 4 | B6: =IFERROR(__xludf.DUMMYFUNCTION("""COMPUTED_VALUE"""),"Saldo Sebelumnya") -> Saldo Sebelumnya | C6: =IFERROR(__xludf.DUMMYFUNCTION("""COMPUTED_VALUE"""),5171000.0) -> 5171000 | D6: =IFERROR(__xludf.DUMMYFUNCTION("QUERY('-Des'!A2:H34, ""SELECT Col1, Col2, Col8 where Col8 > 0"")"),1.0) -> 1 | E6: =IFERROR(__xludf.DUMMYFUNCTION("""COMPUTED_VALUE"""),"Iuran Penjaga Keamanan") -> Iuran Penjaga Keamanan | F6: =IFERROR(__xludf.DUMMYFUNCTION("""COMPUTED_VALUE"""),600000.0) -> 600000
D7: =IFERROR(__xludf.DUMMYFUNCTION("""COMPUTED_VALUE"""),2.0) -> 2 | E7: =IFERROR(__xludf.DUMMYFUNCTION("""COMPUTED_VALUE"""),"Iuran Retribusi Sampah") -> Iuran Retribusi Sampah | F7: =IFERROR(__xludf.DUMMYFUNCTION("""COMPUTED_VALUE"""),75000.0) -> 75000
D8: =IFERROR(__xludf.DUMMYFUNCTION("""COMPUTED_VALUE"""),3.0) -> 3 | E8: =IFERROR(__xludf.DUMMYFUNCTION("""COMPUTED_VALUE"""),"Iuran Tukang Sampah") -> Iuran Tukang Sampah | F8: =IFERROR(__xludf.DUMMYFUNCTION("""COMPUTED_VALUE"""),750000.0) -> 750000
B26: Total Penerimaan | C26: =SUM(C6:C22) -> 5171000 | E26: Total Pengeluaran | F26: =SUM(F6:F22) -> 1425000
E27: Saldo akhir | F27: =SUM(C26-F26) -> 3746000
B32: Rincian Pos
B33: Sampah dan Keamanan | C33: ='+Des'!C80 - '-Des'!C35 -> -3660500
B34: Kematian | C34: ='+Des'!D80 - '-Des'!D35 -> 1607000
B35: Iuran RT | C35: ='+Des'!E80 - '-Des'!E35 -> 741000
B36: Iuran RW | C36: ='+Des'!F80 - '-Des'!F35 -> 1030000
B37: HUT | C37: ='+Des'!G80 - '-Des'!G35 -> 4028500
B38: Total | C38: =SUM(C33:C37) -> 3746000

Sheet +Jan
B1: Nama / Pemasukan | C1: Sampah (35000) | D1: Kematian (5000) | E1: Iuran RT (2500) | F1: Iuran RW (2500) | G1: HUT (5000) | I1: Total (tanpa HUT)
B2: Dama Bu Ifa
A3: 1 | B3: Bu Adim | C3: 35000 | D3: 5000 | E3: 2500 | F3: 2500 | G3: 5000 | I3: =SUM(C3:F3) -> 45000
A4: 2 | B4: Bu Bagus | C4: 35000 | D4: 5000 | E4: 2500 | F4: 2500 | G4: 5000 | I4: =SUM(C4:F4) -> 45000
A5: 3 | B5: Bu Dedy | C5: 35000 | D5: 5000 | E5: 2500 | F5: 2500 | G5: 5000 | I5: =SUM(C5:F5) -> 45000
A6: 4 | B6: Bu Haris | C6: 35000 | D6: 5000 | E6: 2500 | F6: 2500 | G6: 5000 | I6: =SUM(C6:F6) -> 45000
A7: 5 | B7: Bu Ifa | C7: 35000 | D7: 5000 | E7: 2500 | F7: 2500 | G7: 5000 | I7: =SUM(C7:F7) -> 45000
A8: 6 | B8: Bu Lukman | C8: 70000 | D8: 10000 | E8: 2500 | F8: 2500 | G8: 5000 | I8: =SUM(C8:F8) -> 85000
A9: 7 | B9: Bu Lisa | C9: 35000 | D9: 5000 | E9: 2500 | F9: 2500 | G9: 5000 | I9: =SUM(C9:F9) -> 45000
A10: 8 | B10: Bu Nur Badrianto | C10: 35000 | D10: 5000 | E10: 2500 | F10: 2500 | G10: 5000 | I10: =SUM(C10:F10) -> 45000
A11: 9 | B11: Bu Nanang | C11: 35000 | D11: 5000 | E11: 2500 | F11: 2500 | G11: 5000 | I11: =SUM(C11:F11) -> 45000
A12: 10 | B12: Bu Irene | C12: 35000 | D12: 5000 | E12: 2500 | F12: 2500 | G12: 5000 | I12: =SUM(C12:F12) -> 45000
A13: 11 | B13: Bu Aditya | C13: 35000 | D13: 5000 | E13: 2500 | F13: 2500 | G13: 5000 | I13: =SUM(C13:F13) -> 45000
A14: 12 | B14: Bu Roni | C14: 0 | D14: 0 | E14: 0 | F14: 0 | G14: 0 | I14: =SUM(C14:F14) -> 0
... A21: 19 | B21: Bu Handoko | C21: 35000 | D21: 5000 | E21: 2500 | F21: 2500 | G21: 5000 | I21: =SUM(C21:F21) -> 45000
I22: =SUM(I3:I21) -> 715000
B26: Dama Bu Nur Faidzin
A27: 1 | B27: Anggota Dama Bu Nur 1 | C27: 35000 | D27: 5000 | E27: 2500 | F27: 2500 | G27: 5000
A28: 2 | B28: Anggota Dama Bu Nur 2 | C28: 35000 | D28: 5000 | E28: 2500 | F28: 2500 | G28: 5000
A29: 3 | B29: Anggota Dama Bu Nur 3 | C29: 35000 | D29: 5000 | E29: 2500 | F29: 2500 | G29: 5000
A30: 4 | B30: Anggota Dama Bu Nur 4 | C30: 35000 | D30: 5000 | E30: 2500 | F30: 2500 | G30: 5000
A31: 5 | B31: Anggota Dama Bu Nur 5 | C31: 35000 | D31: 5000 | E31: 2500 | F31: 2500 | G31: 5000
A32: 6 | B32: Anggota Dama Bu Nur 6 | C32: 35000 | D32: 5000 | E32: 2500 | F32: 2500 | G32: 5000
A33: 7 | B33: Anggota Dama Bu Nur 7 | C33: 35000 | D33: 5000 | E33: 2500 | F33: 2500 | G33: 5000
A34: 8 | B34: Anggota Dama Bu Nur 8 | C34: 35000 | D34: 5000 | E34: 2500 | F34: 2500 | G34: 5000
A35: 9 | B35: Anggota Dama Bu Nur 9 | C35: 35000 | D35: 5000 | E35: 2500 | F35: 2500 | G35: 5000
A36: 10 | B36: Anggota Dama Bu Nur 10 | C36: 35000 | D36: 5000 | E36: 2500 | F36: 2500 | G36: 5000
A37: 11 | B37: Anggota Dama Bu Nur 11 | C37: 35000 | D37: 5000 | E37: 2500 | F37: 2500 | G37: 5000
A38: 12 | B38: Anggota Dama Bu Nur 12 | C38: 35000 | D38: 5000 | E38: 2500 | F38: 2500 | G38: 5000
... A40: 14 | B40: Anggota Dama Bu Nur 14 | C40: 35000 | D40: 5000 | E40: 2500 | F40: 2500 | G40: 5000
A41: 15 | B41: Yayasan
A42: 16 | B42: Mahasiswa
B46: Anggota Dama Bu Desi
A47: 1 | B47: Pak Abidin S.S. | C47: 35000 | D47: 5000 | E47: 2500 | F47: 2500 | G47: 5000
A48: 2 | B48: Pak Soleh | C48: 35000 | D48: 5000 | E48: 2500 | F48: 2500 | G48: 5000
A49: 3 | B49: Pak Suparto | C49: 35000 | D49: 5000 | E49: 2500 | F49: 2500 | G49: 5000
A50: 4 | B50: Pak Sigit | C50: 35000 | D50: 5000 | E50: 2500 | F50: 2500 | G50: 5000
A51: 5 | B51: Pak Herianto | C51: 35000 | D51: 5000 | E51: 2500 | F51: 2500 | G51: 5000
A52: 6 | B52: Bu Elvin Gunawan | C52: 35000 | D52: 5000 | E52: 2500 | F52: 2500 | G52: 5000
A53: 7 | B53: Pak Boediharjo | C53: 35000 | D53: 5000 | E53: 2500 | F53: 2500 | G53: 5000
...

Sheet +Feb
B1: Nama / Pemasukan | C1: Sampah (35000) | D1: Kematian (5000) | E1: Iuran RT (2500) | F1: Iuran RW (2500) | G1: HUT (10000) | I1: Total (tanpa HUT)
B2: Dama Bu Ifa
A3: 1 | B3: Bu Adim | C3: 35000 | D3: 5000 | E3: 2500 | F3: 2500 | G3: 10000 | I3: =SUM(C3:F3) -> 45000
A4: 2 | B4: Bu Bagus | C4: 35000 | D4: 5000 | E4: 2500 | F4: 2500 | G4: 10000 | I4: =SUM(C4:F4) -> 45000
A5: 3 | B5: Bu Dedy | C5: 35000 | D5: 5000 | E5: 2500 | F5: 2500 | G5: 10000 | I5: =SUM(C5:F5) -> 45000
A6: 4 | B6: Bu Haris | C6: 35000 | D6: 5000 | E6: 2500 | F6: 2500 | G6: 10000 | I6: =SUM(C6:F6) -> 45000
A7: 5 | B7: Bu Ifa | C7: 35000 | D7: 5000 | E7: 2500 | F7: 2500 | G7: 10000 | I7: =SUM(C7:F7) -> 45000
A8: 6 | B8: Bu Lukman | C8: 70000 | D8: 10000 | E8: 2500 | F8: 2500 | G8: 10000 | I8: =SUM(C8:F8) -> 85000
A9: 7 | B9: Bu Lisa | C9: 35000 | D9: 5000 | E9: 2500 | F9: 2500 | G9: 10000 | I9: =SUM(C9:F9) -> 45000
A10: 8 | B10: Bu Nur Badrianto | C10: 35000 | D10: 5000 | E10: 2500 | F10: 2500 | G10: 10000 | I10: =SUM(C10:F10) -> 45000
A11: 9 | B11: Bu Nanang | C11: 35000 | D11: 5000 | E11: 2500 | F11: 2500 | G11: 10000 | I11: =SUM(C11:F11) -> 45000
A12: 10 | B12: Bu Irene | C12: 35000 | D12: 5000 | E12: 2500 | F12: 2500 | G12: 10000 | I12: =SUM(C12:F12) -> 45000
A13: 11 | B13: Bu Aditya | C13: 35000 | D13: 5000 | E13: 2500 | F13: 2500 | G13: 10000 | I13: =SUM(C13:F13) -> 45000
A14: 12 | B14: Bu Roni | C14: 0 | D14: 0 | E14: 0 | F14: 0 | G14: 0 | I14: =SUM(C14:F14) -> 0
... A17: 15 | B17: Bu Wahyu | C17: 0 | D17: 0 | E17: 0 | F17: 0 | G17: 0 | I17: =SUM(C17:F17) -> 0
A18: 16 | B18: Bu Vivi | C18: 0 | D18: 0 | E18: 0 | G18: 0 | I18: =SUM(C18:F18) -> 0
A19: 17 | B19: Bu Yulianus | C19: 35000 | D19: 5000 | E19: 2500 | F19: 2500 | G19: 10000 | I19: =SUM(C19:F19) -> 45000
A20: 18 | B20: Pak Sulton | C20: 0 | D20: 0 | E20: 0 | F20: 0 | G20: 0 | I20: =SUM(C20:F20) -> 0
A21: 19 | B21: Bu Handoko | C21: 70000 | D21: 10000 | E21: 5000 | F21: 5000 | G21: 20000 | I21: =SUM(C21:F21) -> 90000
B26: Dama Bu Nur Faidzin
A27: 1 | B27: Anggota Dama Bu Nur 1 | C27: 35000 | D27: 5000 | E27: 2500 | F27: 2500 | G27: 10000
A28: 2 | B28: Anggota Dama Bu Nur 2 | C28: 35000 | D28: 5000 | E28: 2500 | F28: 2500 | G28: 10000
A29: 3 | B29: Anggota Dama Bu Nur 3 | C29: 35000 | D29: 5000 | E29: 2500 | F29: 2500 | G29: 10000
A30: 4 | B30: Anggota Dama Bu Nur 4 | C30: 35000 | D30: 5000 | E30: 2500 | F30: 2500 | G30: 10000
A31: 5 | B31: Anggota Dama Bu Nur 5 | C31: 35000 | D31: 5000 | E31: 2500 | F31: 2500 | G31: 10000
A32: 6 | B32: Anggota Dama Bu Nur 6 | C32: 35000 | D32: 5000 | E32: 2500 | F32: 2500 | G32: 10000
A33: 7 | B33: Anggota Dama Bu Nur 7 | C33: 35000 | D33: 5000 | E33: 2500 | F33: 2500 | G33: 10000
A34: 8 | B34: Anggota Dama Bu Nur 8 | C34: 35000 | D34: 5000 | E34: 2500 | F34: 2500 | G34: 10000
A35: 9 | B35: Anggota Dama Bu Nur 9 | C35: 35000 | D35: 5000 | E35: 2500 | F35: 2500 | G35: 10000
A36: 10 | B36: Anggota Dama Bu Nur 10 | C36: 35000 | D36: 5000 | E36: 2500 | F36: 2500 | G36: 10000
A37: 11 | B37: Anggota Dama Bu Nur 11 | C37: 35000 | D37: 5000 | E37: 2500 | F37: 2500 | G37: 10000
A38: 12 | B38: Anggota Dama Bu Nur 12 | C38: 35000 | D38: 5000 | E38: 2500 | F38: 2500 | G38: 10000
... A40: 14 | B40: Anggota Dama Bu Nur 14 | C40: 35000 | D40: 5000 | E40: 2500 | F40: 2500 | G40: 10000
A41: 15 | B41: Yayasan
B46: Anggota Dama Bu Desi
A47: 1 | B47: Pak Abidin S.S. | C47: 35000 | D47: 5000 | E47: 2500 | F47: 2500 | G47: 10000
A48: 2 | B48: Pak Soleh | C48: 35000 | D48: 5000 | E48: 2500 | F48: 2500 | G48: 10000
A49: 3 | B49: Pak Suparto | C49: 35000 | D49: 5000 | E49: 2500 | F49: 2500 | G49: 10000
A50: 4 | B50: Pak Sigit | C50: 35000 | D50: 5000 | E50: 2500 | F50: 2500 | G50: 10000
A51: 5 | B51: Pak Herianto | C51: 35000 | D51: 5000 | E51: 2500 | F51: 2500 | G51: 10000
...

Sheet +Mar
B1: Nama / Pemasukan | C1: Sampah (35000) | D1: Kematian (5000) | E1: Iuran RT (2500) | F1: Iuran RW (2500) | G1: HUT (10000) | I1: Total (tanpa HUT)
B2: Dama Bu Ifa
A3: 1 | B3: Bu Adim | C3: 35000 | D3: 5000 | E3: 2500 | F3: 2500 | G3: 10000 | I3: =SUM(C3:F3) -> 45000
A4: 2 | B4: Bu Bagus | C4: 35000 | D4: 5000 | E4: 2500 | F4: 2500 | G4: 10000 | I4: =SUM(C4:F4) -> 45000
A5: 3 | B5: Bu Dedy | C5: 35000 | D5: 5000 | E5: 2500 | F5: 2500 | G5: 10000 | I5: =SUM(C5:F5) -> 45000
A6: 4 | B6: Bu Haris | C6: 35000 | D6: 5000 | E6: 2500 | F6: 2500 | G6: 10000 | I6: =SUM(C6:F6) -> 45000
A7: 5 | B7: Bu Ifa | C7: 35000 | D7: 5000 | E7: 2500 | F7: 2500 | G7: 10000 | I7: =SUM(C7:F7) -> 45000
A8: 6 | B8: Bu Lukman | C8: 70000 | D8: 10000 | E8: 2500 | F8: 2500 | G8: 10000 | I8: =SUM(C8:F8) -> 85000
A9: 7 | B9: Bu Lisa | C9: 35000 | D9: 5000 | E9: 2500 | F9: 2500 | G9: 10000 | I9: =SUM(C9:F9) -> 45000
A10: 8 | B10: Bu Nur Badrianto | C10: 35000 | D10: 5000 | E10: 2500 | F10: 2500 | G10: 10000 | I10: =SUM(C10:F10) -> 45000
A11: 9 | B11: Bu Nanang | C11: 35000 | D11: 5000 | E11: 2500 | F11: 2500 | G11: 10000 | I11: =SUM(C11:F11) -> 45000
A12: 10 | B12: Bu Irene | C12: 35000 | D12: 5000 | E12: 2500 | F12: 2500 | G12: 10000 | I12: =SUM(C12:F12) -> 45000
A13: 11 | B13: Bu Aditya | C13: 35000 | D13: 5000 | E13: 2500 | F13: 2500 | G13: 10000 | I13: =SUM(C13:F13) -> 45000
A14: 12 | B14: Bu Roni | C14: 0 | D14: 0 | E14: 0 | F14: 0 | G14: 0 | I14: =SUM(C14:F14) -> 0
... A21: 19 | B21: Bu Handoko | C21: 0 | D21: 0 | E21: 0 | F21: 0 | G21: 0 | I21: =SUM(C21:F21) -> 0
B26: Dama Bu Nur Faidzin
A27: 1 | B27: Anggota Dama Bu Nur 1 | C27: 35000 | D27: 5000 | E27: 2500 | F27: 2500 | G27: 10000
A28: 2 | B28: Anggota Dama Bu Nur 2 | C28: 35000 | D28: 5000 | E28: 2500 | F28: 2500 | G28: 10000
A29: 3 | B29: Anggota Dama Bu Nur 3 | C29: 35000 | D29: 5000 | E29: 2500 | F29: 2500 | G29: 10000
A30: 4 | B30: Anggota Dama Bu Nur 4 | C30: 35000 | D30: 5000 | E30: 2500 | F30: 2500 | G30: 10000
A31: 5 | B31: Anggota Dama Bu Nur 5 | C31: 35000 | D31: 5000 | E31: 2500 | F31: 2500 | G31: 10000
A32: 6 | B32: Anggota Dama Bu Nur 6 | C32: 35000 | D32: 5000 | E32: 2500 | F32: 2500 | G32: 10000
A33: 7 | B33: Anggota Dama Bu Nur 7 | C33: 35000 | D33: 5000 | E33: 2500 | F33: 2500 | G33: 10000
A34: 8 | B34: Anggota Dama Bu Nur 8 | C34: 35000 | D34: 5000 | E34: 2500 | F34: 2500 | G34: 10000
A35: 9 | B35: Anggota Dama Bu Nur 9 | C35: 35000 | D35: 5000 | E35: 2500 | F35: 2500 | G35: 10000
A36: 10 | B36: Anggota Dama Bu Nur 10 | C36: 35000 | D36: 5000 | E36: 2500 | F36: 2500 | G36: 10000
A37: 11 | B37: Anggota Dama Bu Nur 11 | C37: 35000 | D37: 5000 | E37: 2500 | F37: 2500 | G37: 10000
A38: 12 | B38: Anggota Dama Bu Nur 12 | C38: 35000 | D38: 5000 | E38: 2500 | F38: 2500 | G38: 10000
... A41: 15 | B41: Yayasan | C41: 30000 | D41: 0 | E41: 0 | F41: 0 | G41: 0
B46: Anggota Dama Bu Desi
A47: 1 | B47: Anggota Dama 1 | C47: 35000 | D47: 5000 | E47: 2500 | F47: 2500 | G47: 10000
A48: 2 | B48: Anggota Dama 2 | C48: 35000 | D48: 5000 | E48: 2500 | F48: 2500 | G48: 10000
A49: 3 | B49: Anggota Dama 3 | C49: 35000 | D49: 5000 | E49: 2500 | F49: 2500 | G49: 10000
A50: 4 | B50: Anggota Dama 4 | C50: 35000 | D50: 5000 | E50: 2500 | F50: 2500 | G50: 10000
A51: 5 | B51: Anggota Dama 5 | C51: 35000 | D51: 5000 | E51: 2500 | F51: 2500 | G51: 10000
A52: 6 | B52: Anggota Dama 6 | C52: 35000 | D52: 5000 | E52: 2500 | F52: 2500 | G52: 10000
A53: 7 | B53: Anggota Dama 7 | C53: 35000 | D53: 5000 | E53: 2500 | F53: 2500 | G53: 10000
A54: 8 | B54: Anggota Dama 8 | C54: 35000 | D54: 5000 | E54: 2500 | F54: 2500 | G54: 10000
A55: 9 | B55: Anggota Dama 9 | C55: 35000 | D55: 5000 | E55: 2500 | F55: 2500 | G55: 10000
A56: 10 | B56: Anggota Dama 10 | C56: 35000 | D56: 5000 | E56: 2500 | F56: 2500 | G56: 10000
...

Sheet +Apr
B1: Nama / Pemasukan | C1: Sampah (35000) | D1: Kematian (5000) | E1: Iuran RT (2500) | F1: Iuran RW (2500) | G1: HUT (10000) | I1: Total (tanpa HUT)
B2: Dama Bu Ifa
A3: 1 | B3: Bu Adim | C3: 35000 | D3: 5000 | E3: 2500 | F3: 2500 | G3: 10000 | I3: =SUM(C3:F3) -> 45000
A4: 2 | B4: Bu Bagus | C4: 35000 | D4: 5000 | E4: 2500 | F4: 2500 | G4: 10000 | I4: =SUM(C4:F4) -> 45000
A5: 3 | B5: Bu Dedy | C5: 35000 | D5: 5000 | E5: 2500 | F5: 2500 | G5: 10000 | I5: =SUM(C5:F5) -> 45000
A6: 4 | B6: Bu Haris | C6: 35000 | D6: 5000 | E6: 2500 | F6: 2500 | G6: 10000 | I6: =SUM(C6:F6) -> 45000
A7: 5 | B7: Bu Ifa | C7: 35000 | D7: 5000 | E7: 2500 | F7: 2500 | G7: 10000 | I7: =SUM(C7:F7) -> 45000
A8: 6 | B8: Bu Lukman | C8: 70000 | D8: 10000 | E8: 2500 | F8: 2500 | G8: 10000 | I8: =SUM(C8:F8) -> 85000
A9: 7 | B9: Bu Lisa | C9: 35000 | D9: 5000 | E9: 2500 | F9: 2500 | G9: 10000 | I9: =SUM(C9:F9) -> 45000
A10: 8 | B10: Bu Nur Badrianto | C10: 35000 | D10: 5000 | E10: 2500 | F10: 2500 | G10: 10000 | I10: =SUM(C10:F10) -> 45000
A11: 9 | B11: Bu Nanang | C11: 35000 | D11: 5000 | E11: 2500 | F11: 2500 | G11: 10000 | I11: =SUM(C11:F11) -> 45000
A12: 10 | B12: Bu Irene | C12: 35000 | D12: 5000 | E12: 2500 | F12: 2500 | G12: 10000 | I12: =SUM(C12:F12) -> 45000
A13: 11 | B13: Bu Aditya | C13: 35000 | D13: 5000 | E13: 2500 | F13: 2500 | G13: 10000 | I13: =SUM(C13:F13) -> 45000
A14: 12 | B14: Bu Roni | C14: 0 | D14: 0 | E14: 0 | F14: 0 | G14: 0 | I14: =SUM(C14:F14) -> 0
... A21: 19 | B21: Bu Handoko | C21: 35000 | D21: 5000 | E21: 2500 | F21: 2500 | G21: 10000 | I21: =SUM(C21:F21) -> 45000
B26: Dama Bu Nur Faidzin
A27: 1 | B27: Anggota Dama Bu Nur 1 | C27: 35000 | D27: 5000 | E27: 2500 | F27: 2500 | G27: 10000
A28: 2 | B28: Anggota Dama Bu Nur 2 | C28: 35000 | D28: 5000 | E28: 2500 | F28: 2500 | G28: 10000
A29: 3 | B29: Anggota Dama Bu Nur 3 | C29: 35000 | D29: 5000 | E29: 2500 | F29: 2500 | G29: 10000
A30: 4 | B30: Anggota Dama Bu Nur 4 | C30: 35000 | D30: 5000 | E30: 2500 | F30: 2500 | G30: 10000
A31: 5 | B31: Anggota Dama Bu Nur 5 | C31: 35000 | D31: 5000 | E31: 2500 | F31: 2500 | G31: 10000
A32: 6 | B32: Anggota Dama Bu Nur 6 | C32: 35000 | D32: 5000 | E32: 2500 | F32: 2500 | G32: 10000
A33: 7 | B33: Anggota Dama Bu Nur 7 | C33: 35000 | D33: 5000 | E33: 2500 | F33: 2500 | G33: 10000
A34: 8 | B34: Anggota Dama Bu Nur 8 | C34: 35000 | D34: 5000 | E34: 2500 | F34: 2500 | G34: 10000
A35: 9 | B35: Anggota Dama Bu Nur 9 | C35: 35000 | D35: 5000 | E35: 2500 | F35: 2500 | G35: 10000
A36: 10 | B36: Anggota Dama Bu Nur 10 | C36: 35000 | D36: 5000 | E36: 2500 | F36: 2500 | G36: 10000
A37: 11 | B37: Anggota Dama Bu Nur 11 | C37: 35000 | D37: 5000 | E37: 2500 | F37: 2500 | G37: 10000
A38: 12 | B38: Anggota Dama Bu Nur 12 | C38: 35000 | D38: 5000 | E38: 2500 | F38: 2500 | G38: 10000
... A41: 15 | B41: Anggota Dama Bu Nur 15 | C41: 30000 | D41: 5000 | E41: 2500 | F41: 2500 | G41: 10000
B46: Anggota Dama Bu Desi
A47: 1 | B47: Anggota Dama 1 | C47: 35000 | D47: 5000 | E47: 2500 | F47: 2500 | G47: 10000
A48: 2 | B48: Anggota Dama 2 | C48: 35000 | D48: 5000 | E48: 2500 | F48: 2500 | G48: 10000
A49: 3 | B49: Anggota Dama 3 | C49: 35000 | D49: 5000 | E49: 2500 | F49: 2500 | G49: 10000
A50: 4 | B50: Anggota Dama 4 | C50: 35000 | D50: 5000 | E50: 2500 | F50: 2500 | G50: 10000
A51: 5 | B51: Anggota Dama 5 | C51: 35000 | D51: 5000 | E51: 2500 | F51: 2500 | G51: 10000
A52: 6 | B52: Anggota Dama 6 | C52: 35000 | D52: 5000 | E52: 2500 | F52: 2500 | G52: 10000
A53: 7 | B53: Anggota Dama 7 | C53: 35000 | D53: 5000 | E53: 2500 | F53: 2500 | G53: 10000
A54: 8 | B54: Anggota Dama 8 | C54: 35000 | D54: 5000 | E54: 2500 | F54: 2500 | G54: 10000
A55: 9 | B55: Anggota Dama 9 | C55: 35000 | D55: 5000 | E55: 2500 | F55: 2500 | G55: 10000
A56: 10 | B56: Anggota Dama 10 | C56: 35000 | D56: 5000 | E56: 2500 | F56: 2500 | G56: 10000
...

Sheet +Mei
B1: Nama / Pemasukan | C1: Sampah (35000) | D1: Kematian (5000) | E1: Iuran RT (2500) | F1: Iuran RW (2500) | G1: HUT (10000) | I1: Total (tanpa HUT)
B2: Dama Bu Ifa
A3: 1 | B3: Bu Adim | C3: 35000 | D3: 5000 | E3: 2500 | F3: 2500 | G3: 10000 | I3: =SUM(C3:F3) -> 45000
A4: 2 | B4: Bu Bagus | C4: 35000 | D4: 5000 | E4: 2500 | F4: 2500 | G4: 10000 | I4: =SUM(C4:F4) -> 45000
A5: 3 | B5: Bu Dedy | C5: 35000 | D5: 5000 | E5: 2500 | F5: 2500 | G5: 10000 | I5: =SUM(C5:F5) -> 45000
A6: 4 | B6: Bu Haris | C6: 35000 | D6: 5000 | E6: 2500 | F6: 2500 | G6: 10000 | I6: =SUM(C6:F6) -> 45000
A7: 5 | B7: Bu Ifa | C7: 35000 | D7: 5000 | E7: 2500 | F7: 2500 | G7: 10000 | I7: =SUM(C7:F7) -> 45000
A8: 6 | B8: Bu Lukman | C8: 70000 | D8: 10000 | E8: 2500 | F8: 2500 | G8: 10000 | I8: =SUM(C8:F8) -> 85000
A9: 7 | B9: Bu Lisa | C9: 35000 | D9: 5000 | E9: 2500 | F9: 2500 | G9: 10000 | I9: =SUM(C9:F9) -> 45000
A10: 8 | B10: Bu Nur Badrianto | C10: 35000 | D10: 5000 | E10: 2500 | F10: 2500 | G10: 10000 | I10: =SUM(C10:F10) -> 45000
A11: 9 | B11: Bu Nanang | C11: 35000 | D11: 5000 | E11: 2500 | F11: 2500 | G11: 10000 | I11: =SUM(C11:F11) -> 45000
A12: 10 | B12: Bu Irene | C12: 35000 | D12: 5000 | E12: 2500 | F12: 2500 | G12: 10000 | I12: =SUM(C12:F12) -> 45000
A13: 11 | B13: Bu Aditya | C13: 35000 | D13: 5000 | E13: 2500 | F13: 2500 | G13: 10000 | I13: =SUM(C13:F13) -> 45000
A14: 12 | B14: Bu Roni | C14: 0 | D14: 0 | E14: 0 | F14: 0 | G14: 0 | I14: =SUM(C14:F14) -> 0
... A20: 18 | B20: Pak Sulton | C20: 0 | D20: 0 | E20: 0 | F20: 0 | G20: 0 | I20: =SUM(C20:F20) -> 0
A21: 19 | B21: Bu Handoko | I21: =SUM(C21:F21) -> 0
B26: Dama Bu Nur Faidzin
A27: 1 | B27: Anggota Dama Bu Nur 1 | C27: 35000 | D27: 5000 | E27: 2500 | F27: 2500 | G27: 10000
A28: 2 | B28: Anggota Dama Bu Nur 2 | C28: 35000 | D28: 5000 | E28: 2500 | F28: 2500 | G28: 10000
A29: 3 | B29: Anggota Dama Bu Nur 3 | C29: 35000 | D29: 5000 | E29: 2500 | F29: 2500 | G29: 10000
A30: 4 | B30: Anggota Dama Bu Nur 4 | C30: 35000 | D30: 5000 | E30: 2500 | F30: 2500 | G30: 10000
A31: 5 | B31: Anggota Dama Bu Nur 5 | C31: 35000 | D31: 5000 | E31: 2500 | F31: 2500 | G31: 10000
A32: 6 | B32: Anggota Dama Bu Nur 6 | C32: 35000 | D32: 5000 | E32: 2500 | F32: 2500 | G32: 10000
A33: 7 | B33: Anggota Dama Bu Nur 7 | C33: 35000 | D33: 5000 | E33: 2500 | F33: 2500 | G33: 10000
A34: 8 | B34: Anggota Dama Bu Nur 8 | C34: 35000 | D34: 5000 | E34: 2500 | F34: 2500 | G34: 10000
A35: 9 | B35: Anggota Dama Bu Nur 9 | C35: 35000 | D35: 5000 | E35: 2500 | F35: 2500 | G35: 10000
A36: 10 | B36: Anggota Dama Bu Nur 10 | C36: 35000 | D36: 5000 | E36: 2500 | F36: 2500 | G36: 10000
A37: 11 | B37: Anggota Dama Bu Nur 11 | C37: 35000 | D37: 5000 | E37: 2500 | F37: 2500 | G37: 10000
A38: 12 | B38: Anggota Dama Bu Nur 12 | C38: 35000 | D38: 5000 | E38: 2500 | F38: 2500 | G38: 10000
... A43: 17 | B43: Yayasan | C43: 30000 | D43: 0 | E43: 0 | F43: 0 | G43: 0
B46: Anggota Dama Bu Desi
A47: 1 | B47: Anggota Dama 1
A48: 2 | B48: Anggota Dama 2
A49: 3 | B49: Anggota Dama 3
A50: 4 | B50: Anggota Dama 4
A51: 5 | B51: Anggota Dama 5
A52: 6 | B52: Anggota Dama 6
A53: 7 | B53: Anggota Dama 7
A54: 8 | B54: Anggota Dama 8
A55: 9 | B55: Anggota Dama 9
...

Sheet +Jun
B1: Nama / Pemasukan | C1: Sampah (35000) | D1: Kematian (5000) | E1: Iuran RT (2500) | F1: Iuran RW (2500) | G1: HUT (10000) | I1: Total (tanpa HUT)
B2: Dama Bu Ifa
A3: 1 | B3: Bu Adim | C3: 35000 | D3: 5000 | E3: 2500 | F3: 2500 | G3: 10000 | I3: =SUM(C3:F3) -> 45000
A4: 2 | B4: Bu Bagus | C4: 35000 | D4: 5000 | E4: 2500 | F4: 2500 | G4: 10000 | I4: =SUM(C4:F4) -> 45000
A5: 3 | B5: Bu Dedy | C5: 35000 | D5: 5000 | E5: 2500 | F5: 2500 | G5: 10000 | I5: =SUM(C5:F5) -> 45000
A6: 4 | B6: Bu Haris | C6: 35000 | D6: 5000 | E6: 2500 | F6: 2500 | G6: 10000 | I6: =SUM(C6:F6) -> 45000
A7: 5 | B7: Bu Ifa | C7: 35000 | D7: 5000 | E7: 2500 | F7: 2500 | G7: 10000 | I7: =SUM(C7:F7) -> 45000
A8: 6 | B8: Bu Lukman | C8: 70000 | D8: 10000 | E8: 2500 | F8: 2500 | G8: 10000 | I8: =SUM(C8:F8) -> 85000
A9: 7 | B9: Bu Lisa | C9: 35000 | D9: 5000 | E9: 2500 | F9: 2500 | G9: 10000 | I9: =SUM(C9:F9) -> 45000
A10: 8 | B10: Bu Nur Badrianto | C10: 35000 | D10: 5000 | E10: 2500 | F10: 2500 | G10: 10000 | I10: =SUM(C10:F10) -> 45000
A11: 9 | B11: Bu Nanang | C11: 35000 | D11: 5000 | E11: 2500 | F11: 2500 | G11: 10000 | I11: =SUM(C11:F11) -> 45000
A12: 10 | B12: Bu Irene | C12: 35000 | D12: 5000 | E12: 2500 | F12: 2500 | G12: 10000 | I12: =SUM(C12:F12) -> 45000
A13: 11 | B13: Bu Aditya | C13: 35000 | D13: 5000 | E13: 2500 | F13: 2500 | G13: 10000 | I13: =SUM(C13:F13) -> 45000
A14: 12 | B14: Bu Roni | C14: 0 | D14: 0 | E14: 0 | F14: 0 | G14: 0 | I14: =SUM(C14:F14) -> 0
... A20: 18 | B20: Pak Sulton | C20: 0 | D20: 0 | E20: 0 | F20: 0 | G20: 0 | I20: =SUM(C20:F20) -> 0
A21: 19 | B21: Bu Handoko | I21: =SUM(C21:F21) -> 0
B26: Dama Bu Nur Faidzin
A27: 1 | B27: Anggota Dama Bu Nur 1
A28: 2 | B28: Anggota Dama Bu Nur 2
A29: 3 | B29: Anggota Dama Bu Nur 3
A30: 4 | B30: Anggota Dama Bu Nur 4
A31: 5 | B31: Anggota Dama Bu Nur 5
A32: 6 | B32: Anggota Dama Bu Nur 6
A33: 7 | B33: Anggota Dama Bu Nur 7
A34: 8 | B34: Anggota Dama Bu Nur 8
A35: 9 | B35: Anggota Dama Bu Nur 9
A36: 10 | B36: Anggota Dama Bu Nur 10
A37: 11 | B37: Anggota Dama Bu Nur 11
A38: 12 | B38: Anggota Dama Bu Nur 12
... A40: 14 | B40: Anggota Dama Bu Nur 14
B46: Anggota Dama Bu Desi
A47: 1 | B47: Anggota Dama 1
A48: 2 | B48: Anggota Dama 2
A49: 3 | B49: Anggota Dama 3
A50: 4 | B50: Anggota Dama 4
A51: 5 | B51: Anggota Dama 5
A52: 6 | B52: Anggota Dama 6
A53: 7 | B53: Anggota Dama 7
A54: 8 | B54: Anggota Dama 8
A55: 9 | B55: Anggota Dama 9
...

Sheet +Jul
B1: Nama / Pemasukan | C1: Sampah (35000) | D1: Kematian (5000) | E1: Iuran RT (2500) | F1: Iuran RW (2500) | G1: HUT (10000) | I1: Total (tanpa HUT)
B2: Dama Bu Ifa
A3: 1 | B3: Bu Adim | I3: =SUM(C3:F3) -> 0
A4: 2 | B4: Bu Bagus | I4: =SUM(C4:F4) -> 0
A5: 3 | B5: Bu Dedy | I5: =SUM(C5:F5) -> 0
A6: 4 | B6: Bu Haris | I6: =SUM(C6:F6) -> 0
A7: 5 | B7: Bu Ifa | I7: =SUM(C7:F7) -> 0
A8: 6 | B8: Bu Lukman | I8: =SUM(C8:F8) -> 0
A9: 7 | B9: Bu Lisa | I9: =SUM(C9:F9) -> 0
A10: 8 | B10: Bu Nur Badrianto | I10: =SUM(C10:F10) -> 0
A11: 9 | B11: Bu Nanang | I11: =SUM(C11:F11) -> 0
A12: 10 | B12: Bu Irene | I12: =SUM(C12:F12) -> 0
A13: 11 | B13: Bu Aditya | I13: =SUM(C13:F13) -> 0
A14: 12 | B14: Bu Roni | I14: =SUM(C14:F14) -> 0
... A21: 19 | B21: Bu Handoko | I21: =SUM(C21:F21) -> 0
B26: Dama Bu Nur Faidzin
A27: 1 | B27: Anggota Dama Bu Nur 1
A28: 2 | B28: Anggota Dama Bu Nur 2
A29: 3 | B29: Anggota Dama Bu Nur 3
A30: 4 | B30: Anggota Dama Bu Nur 4
A31: 5 | B31: Anggota Dama Bu Nur 5
A32: 6 | B32: Anggota Dama Bu Nur 6
A33: 7 | B33: Anggota Dama Bu Nur 7
A34: 8 | B34: Anggota Dama Bu Nur 8
A35: 9 | B35: Anggota Dama Bu Nur 9
A36: 10 | B36: Anggota Dama Bu Nur 10
A37: 11 | B37: Anggota Dama Bu Nur 11
A38: 12 | B38: Anggota Dama Bu Nur 12
... A40: 14 | B40: Anggota Dama Bu Nur 14
B46: Anggota Dama Bu Desi
A47: 1 | B47: Anggota Dama 1
A48: 2 | B48: Anggota Dama 2
A49: 3 | B49: Anggota Dama 3
A50: 4 | B50: Anggota Dama 4
A51: 5 | B51: Anggota Dama 5
A52: 6 | B52: Anggota Dama 6
A53: 7 | B53: Anggota Dama 7
A54: 8 | B54: Anggota Dama 8
A55: 9 | B55: Anggota Dama 9
A56: 10 | B56: Anggota Dama 10
...

Sheet +Agu
B1: Nama / Pemasukan | C1: Sampah (35000) | D1: Kematian (5000) | E1: Iuran RT (2500) | F1: Iuran RW (2500) | G1: HUT (10000) | I1: Total (tanpa HUT)
B2: Dama Bu Ifa
A3: 1 | B3: Bu Adim | I3: =SUM(C3:F3) -> 0
A4: 2 | B4: Bu Bagus | I4: =SUM(C4:F4) -> 0
A5: 3 | B5: Bu Dedy | I5: =SUM(C5:F5) -> 0
A6: 4 | B6: Bu Haris | I6: =SUM(C6:F6) -> 0
A7: 5 | B7: Bu Ifa | I7: =SUM(C7:F7) -> 0
A8: 6 | B8: Bu Lukman | I8: =SUM(C8:F8) -> 0
A9: 7 | B9: Bu Lisa | I9: =SUM(C9:F9) -> 0
A10: 8 | B10: Bu Nur Badrianto | I10: =SUM(C10:F10) -> 0
A11: 9 | B11: Bu Nanang | I11: =SUM(C11:F11) -> 0
A12: 10 | B12: Bu Irene | I12: =SUM(C12:F12) -> 0
A13: 11 | B13: Bu Aditya | I13: =SUM(C13:F13) -> 0
A14: 12 | B14: Bu Roni | I14: =SUM(C14:F14) -> 0
... A21: 19 | B21: Bu Handoko | I21: =SUM(C21:F21) -> 0
B26: Dama Bu Nur Faidzin
A27: 1 | B27: Anggota Dama Bu Nur 1
A28: 2 | B28: Anggota Dama Bu Nur 2
A29: 3 | B29: Anggota Dama Bu Nur 3
A30: 4 | B30: Anggota Dama Bu Nur 4
A31: 5 | B31: Anggota Dama Bu Nur 5
A32: 6 | B32: Anggota Dama Bu Nur 6
A33: 7 | B33: Anggota Dama Bu Nur 7
A34: 8 | B34: Anggota Dama Bu Nur 8
A35: 9 | B35: Anggota Dama Bu Nur 9
A36: 10 | B36: Anggota Dama Bu Nur 10
A37: 11 | B37: Anggota Dama Bu Nur 11
A38: 12 | B38: Anggota Dama Bu Nur 12
... A42: 16 | B42: Mahasiswa
B46: Anggota Dama Bu Desi
A47: 1 | B47: Anggota Dama 1
A48: 2 | B48: Anggota Dama 2
A49: 3 | B49: Anggota Dama 3
A50: 4 | B50: Anggota Dama 4
A51: 5 | B51: Anggota Dama 5
A52: 6 | B52: Anggota Dama 6
A53: 7 | B53: Anggota Dama 7
A54: 8 | B54: Anggota Dama 8
A55: 9 | B55: Anggota Dama 9
A56: 10 | B56: Anggota Dama 10
...

Sheet +Sep
B1: Nama / Pemasukan | C1: Sampah (35000) | D1: Kematian (5000) | E1: Iuran RT (2500) | F1: Iuran RW (2500) | G1: HUT (10000) | I1: Total (tanpa HUT)
B2: Dama Bu Ifa
A3: 1 | B3: Bu Adim | I3: =SUM(C3:F3) -> 0
A4: 2 | B4: Bu Bagus | I4: =SUM(C4:F4) -> 0
A5: 3 | B5: Bu Dedy | I5: =SUM(C5:F5) -> 0
A6: 4 | B6: Bu Haris | I6: =SUM(C6:F6) -> 0
A7: 5 | B7: Bu Ifa | I7: =SUM(C7:F7) -> 0
A8: 6 | B8: Bu Lukman | I8: =SUM(C8:F8) -> 0
A9: 7 | B9: Bu Lisa | I9: =SUM(C9:F9) -> 0
A10: 8 | B10: Bu Nur Badrianto | I10: =SUM(C10:F10) -> 0
A11: 9 | B11: Bu Nanang | I11: =SUM(C11:F11) -> 0
A12: 10 | B12: Bu Irene | I12: =SUM(C12:F12) -> 0
A13: 11 | B13: Bu Aditya | I13: =SUM(C13:F13) -> 0
A14: 12 | B14: Bu Roni | I14: =SUM(C14:F14) -> 0
... A21: 19 | B21: Bu Handoko | I21: =SUM(C21:F21) -> 0
B26: Dama Bu Nur Faidzin
A27: 1 | B27: Anggota Dama Bu Nur 1
A28: 2 | B28: Anggota Dama Bu Nur 2
A29: 3 | B29: Anggota Dama Bu Nur 3
A30: 4 | B30: Anggota Dama Bu Nur 4
A31: 5 | B31: Anggota Dama Bu Nur 5
A32: 6 | B32: Anggota Dama Bu Nur 6
A33: 7 | B33: Anggota Dama Bu Nur 7
A34: 8 | B34: Anggota Dama Bu Nur 8
A35: 9 | B35: Anggota Dama Bu Nur 9
A36: 10 | B36: Anggota Dama Bu Nur 10
A37: 11 | B37: Anggota Dama Bu Nur 11
A38: 12 | B38: Anggota Dama Bu Nur 12
... A42: 16 | B42: Mahasiswa
B46: Anggota Dama Bu Desi
A47: 1 | B47: Anggota Dama 1
A48: 2 | B48: Anggota Dama 2
A49: 3 | B49: Anggota Dama 3
A50: 4 | B50: Anggota Dama 4
A51: 5 | B51: Anggota Dama 5
A52: 6 | B52: Anggota Dama 6
A53: 7 | B53: Anggota Dama 7
A54: 8 | B54: Anggota Dama 8
A55: 9 | B55: Anggota Dama 9
A56: 10 | B56: Anggota Dama 10
...

Sheet +Okt
B1: Nama / Pemasukan | C1: Sampah (35000) | D1: Kematian (5000) | E1: Iuran RT (2500) | F1: Iuran RW (2500) | G1: HUT (10000) | H1: Total | I1: Total (tanpa HUT)
B2: Dama Bu Ifa
A3: 1 | B3: Bu Adim | I3: =SUM(C3:F3) -> 0
A4: 2 | B4: Bu Bagus | I4: =SUM(C4:F4) -> 0
A5: 3 | B5: Bu Dedy | I5: =SUM(C5:F5) -> 0
A6: 4 | B6: Bu Haris | I6: =SUM(C6:F6) -> 0
A7: 5 | B7: Bu Ifa | I7: =SUM(C7:F7) -> 0
A8: 6 | B8: Bu Lukman | I8: =SUM(C8:F8) -> 0
A9: 7 | B9: Bu Lisa | I9: =SUM(C9:F9) -> 0
A10: 8 | B10: Bu Nur Badrianto | I10: =SUM(C10:F10) -> 0
A11: 9 | B11: Bu Nanang | I11: =SUM(C11:F11) -> 0
A12: 10 | B12: Bu Irene | I12: =SUM(C12:F12) -> 0
A13: 11 | B13: Bu Aditya | I13: =SUM(C13:F13) -> 0
A14: 12 | B14: Bu Roni | I14: =SUM(C14:F14) -> 0
... A21: 19 | B21: Bu Handoko | I21: =SUM(C21:F21) -> 0
B26: Dama Bu Nur Faidzin
A27: 1 | B27: Anggota Dama Bu Nur 1
A28: 2 | B28: Anggota Dama Bu Nur 2
A29: 3 | B29: Anggota Dama Bu Nur 3
A30: 4 | B30: Anggota Dama Bu Nur 4
A31: 5 | B31: Anggota Dama Bu Nur 5
A32: 6 | B32: Anggota Dama Bu Nur 6
A33: 7 | B33: Anggota Dama Bu Nur 7
A34: 8 | B34: Anggota Dama Bu Nur 8
A35: 9 | B35: Anggota Dama Bu Nur 9
A36: 10 | B36: Anggota Dama Bu Nur 10
A37: 11 | B37: Anggota Dama Bu Nur 11
A38: 12 | B38: Anggota Dama Bu Nur 12
... A42: 16 | B42: Mahasiswa
B46: Anggota Dama Bu Desi
A47: 1 | B47: Anggota Dama 1
A48: 2 | B48: Anggota Dama 2
A49: 3 | B49: Anggota Dama 3
A50: 4 | B50: Anggota Dama 4
A51: 5 | B51: Anggota Dama 5
A52: 6 | B52: Anggota Dama 6
A53: 7 | B53: Anggota Dama 7
A54: 8 | B54: Anggota Dama 8
A55: 9 | B55: Anggota Dama 9
A56: 10 | B56: Anggota Dama 10
...

Sheet +Nov
B1: Nama / Pemasukan | C1: Sampah (35000) | D1: Kematian (5000) | E1: Iuran RT (2500) | F1: Iuran RW (2500) | G1: HUT (10000) | I1: Total (tanpa HUT)
B2: Dama Bu Ifa
A3: 1 | B3: Bu Adim | I3: =SUM(C3:F3) -> 0
A4: 2 | B4: Bu Bagus | I4: =SUM(C4:F4) -> 0
A5: 3 | B5: Bu Dedy | I5: =SUM(C5:F5) -> 0
A6: 4 | B6: Bu Haris | I6: =SUM(C6:F6) -> 0
A7: 5 | B7: Bu Ifa | I7: =SUM(C7:F7) -> 0
A8: 6 | B8: Bu Lukman | I8: =SUM(C8:F8) -> 0
A9: 7 | B9: Bu Lisa | I9: =SUM(C9:F9) -> 0
A10: 8 | B10: Bu Nur Badrianto | I10: =SUM(C10:F10) -> 0
A11: 9 | B11: Bu Nanang | I11: =SUM(C11:F11) -> 0
A12: 10 | B12: Bu Irene | I12: =SUM(C12:F12) -> 0
A13: 11 | B13: Bu Aditya | I13: =SUM(C13:F13) -> 0
A14: 12 | B14: Bu Roni | I14: =SUM(C14:F14) -> 0
... A21: 19 | B21: Bu Handoko | I21: =SUM(C21:F21) -> 0
B26: Dama Bu Nur Faidzin
A27: 1 | B27: Anggota Dama Bu Nur 1
A28: 2 | B28: Anggota Dama Bu Nur 2
A29: 3 | B29: Anggota Dama Bu Nur 3
A30: 4 | B30: Anggota Dama Bu Nur 4
A31: 5 | B31: Anggota Dama Bu Nur 5
A32: 6 | B32: Anggota Dama Bu Nur 6
A33: 7 | B33: Anggota Dama Bu Nur 7
A34: 8 | B34: Anggota Dama Bu Nur 8
A35: 9 | B35: Anggota Dama Bu Nur 9
A36: 10 | B36: Anggota Dama Bu Nur 10
A37: 11 | B37: Anggota Dama Bu Nur 11
A38: 12 | B38: Anggota Dama Bu Nur 12
... A42: 16 | B42: Mahasiswa
B46: Anggota Dama Bu Desi
A47: 1 | B47: Anggota Dama 1
A48: 2 | B48: Anggota Dama 2
A49: 3 | B49: Anggota Dama 3
A50: 4 | B50: Anggota Dama 4
A51: 5 | B51: Anggota Dama 5
A52: 6 | B52: Anggota Dama 6
A53: 7 | B53: Anggota Dama 7
A54: 8 | B54: Anggota Dama 8
A55: 9 | B55: Anggota Dama 9
A56: 10 | B56: Anggota Dama 10
...

Sheet +Des
B1: Nama / Pemasukan | C1: Sampah (35000) | D1: Kematian (5000) | E1: Iuran RT (2500) | F1: Iuran RW (2500) | G1: HUT (10000) | I1: Total (tanpa HUT)
B2: Dama Bu Ifa
